import asyncio
from pathlib import Path

import pytest

from protostar.commands.test.test_result_formatter import format_test_result
from protostar.testing import TestingSummary
from protostar.testing.test_results import BrokenTestCaseResult
from tests.integration.conftest import (
    RunTestRunnerFixture,
    assert_cairo_test_cases,
)


@pytest.fixture(name="testing_summary", scope="module")
def testing_summary_fixture(
    run_test_runner: RunTestRunnerFixture,
) -> TestingSummary:
    return asyncio.run(
        run_test_runner(Path(__file__).parent / "expect_revert_test.cairo")
    )


async def test_test_result_types(testing_summary: TestingSummary):
    assert_cairo_test_cases(
        testing_summary,
        expected_passed_test_cases_names=[
            "test_partial_error_message",
            "test_call_not_existing_contract_err_message",
            "test_call_not_existing_contract",
            "test_error_message",
            "test_with_except_revert",
        ],
        expected_failed_test_cases_names=[
            "test_error_was_not_raised_before_stopping_expect_revert_fail_expected",
            "test_call_not_existing_contract_fail_expected",
            "test_with_except_out_of_scope_revert_fail_expected",
            "test_with_except_revert_fail_expected",
            "test_fail_error_message",
        ],
        expected_broken_test_cases_names=[
            "test_already_expecting_error_message_when_no_arguments_were_provided"
        ],
    )


async def test_already_expecting_error_message_when_no_arguments_were_provided(
    testing_summary: TestingSummary,
):

    test_result = testing_summary[
        "test_already_expecting_error_message_when_no_arguments_were_provided"
    ]
    formatted_test_result = format_test_result(test_result)

    assert isinstance(test_result, BrokenTestCaseResult)
    assert "matching the following error" not in formatted_test_result
    assert "Protostar is already expecting an exception" in formatted_test_result
